<?xml version="1.0" ?>
<!-- =================================================================================== -->
<!-- |    This document was autogenerated by xacro from schunk_lwa4p_standalone.urdf.xacro | -->
<!-- |    EDITING THIS FILE BY HAND IS NOT RECOMMENDED                                 | -->
<!-- =================================================================================== -->
<robot name="lwa4p" xmlns:xacro="http://ros.org/wiki/xacro">
  <!-- common stuff -->
  <material name="schunk_light_grey">
    <color rgba="0.7 0.7 0.7 1.0"/>
  </material>
  <material name="schunk_dark_grey">
    <color rgba="0.4 0.4 0.4 1.0"/>
  </material>
  <material name="schunk_black">
    <color rgba="0.0 0.0 0.0 1.0"/>
  </material>
  <material name="schunk_dark_golden">
    <color rgba="0.4 0.4 0.3 1.0"/>
  </material>
  <material name="schunk_blue">
    <color rgba="0.0 0.0 0.8 1.0"/>
  </material>
  <!-- calibration -->
  <!-- schunk powerball -->
  <!--include filename="$(find robotnik_powerball_basics)/urdf/powerball_robotnik.urdf.xacro"/-->
  <!-- foot for arm -->
  <link name="base_link">

	</link>
  <!-- LEFT ARM -->
  <joint name="lwa4p_arm_0_joint" type="fixed">
    <origin rpy="0 0 0" xyz="0 0 0"/>
    <parent link="base_link"/>
    <child link="lwa4p_arm_0_link"/>
  </joint>
  <link name="lwa4p_arm_0_link">
    <inertial>
      <origin rpy="0 0 0" xyz="0 0 0"/>
      <mass value="0.29364"/>
      <inertia ixx="0.01" ixy="0" ixz="0" iyy="0.01" iyz="0" izz="0.01"/>
    </inertial>
    <visual>
      <origin rpy="0 0 0" xyz="0 0 0"/>
      <geometry>
        <mesh filename="package://crom_description/meshes/arms/lwa4p/stl/arm_base.stl"/>
      </geometry>
      <material name="schunk_light_grey"/>
    </visual>
    <collision>
      <origin rpy="0 0 0" xyz="0 0 0"/>
      <geometry>
        <mesh filename="package://crom_description/meshes/arms/lwa4p/stl/arm_base.stl"/>
      </geometry>
    </collision>
  </link>
  <joint name="lwa4p_arm_1_joint" type="revolute">
    <origin rpy="0 0 0" xyz="0 0 0.2051"/>
    <parent link="lwa4p_arm_0_link"/>
    <child link="lwa4p_arm_1_link"/>
    <axis xyz="0 0 1"/>
    <calibration rising="0"/>
    <dynamics damping="10"/>
    <limit effort="370" lower="-2.967059678" upper="2.967059678" velocity="1.25663706144"/>
    <safety_controller k_position="20" k_velocity="50" soft_lower_limit="-6.2731853" soft_upper_limit="6.2731853"/>
  </joint>
  <link name="lwa4p_arm_1_link">
    <inertial>
      <origin rpy="0 0 0" xyz="0 0 0"/>
      <mass value="0.29364"/>
      <inertia ixx="0.01" ixy="0" ixz="0" iyy="0.01" iyz="0" izz="0.01"/>
    </inertial>
    <visual>
      <origin rpy="0 0 0" xyz="0 0 0"/>
      <geometry>
        <mesh filename="package://crom_description/meshes/arms/lwa4p/stl/arm_1_link.stl"/>
      </geometry>
      <material name="schunk_light_grey"/>
    </visual>
    <collision>
      <origin rpy="0 0 0" xyz="0 0 0"/>
      <geometry>
        <mesh filename="package://crom_description/meshes/arms/lwa4p/stl/arm_1_link.stl"/>
      </geometry>
    </collision>
  </link>
  <joint name="lwa4p_arm_2_joint" type="revolute">
    <origin rpy="1.5708 0 0" xyz="0 0 0"/>
    <parent link="lwa4p_arm_1_link"/>
    <child link="lwa4p_arm_2_link"/>
    <axis xyz="0 0 1"/>
    <calibration rising="0"/>
    <dynamics damping="10"/>
    <limit effort="370" lower="-1.919862144" upper="1.919862144" velocity="1.25663706144"/>
    <safety_controller k_position="20" k_velocity="50" soft_lower_limit="-2.0843" soft_upper_limit="2.0843"/>
  </joint>
  <link name="lwa4p_arm_2_link">
    <inertial>
      <origin rpy="0 0 0" xyz="0 0 0"/>
      <mass value="1.68311"/>
      <inertia ixx="0.03" ixy="0" ixz="0" iyy="0.03" iyz="0" izz="0.03"/>
    </inertial>
    <visual>
      <origin rpy="0 0 0" xyz="0 0 0"/>
      <geometry>
        <mesh filename="package://crom_description/meshes/arms/lwa4p/stl/arm_2_link.stl"/>
      </geometry>
      <material name="schunk_blue"/>
    </visual>
    <collision>
      <origin rpy="0 0 0" xyz="0 0 0"/>
      <geometry>
        <mesh filename="package://crom_description/meshes/arms/lwa4p/stl/arm_2_link.stl"/>
      </geometry>
    </collision>
  </link>
  <joint name="lwa4p_arm_3_joint" type="revolute">
    <origin rpy="0 3.14159 0" xyz="0 0.350 0"/>
    <parent link="lwa4p_arm_2_link"/>
    <child link="lwa4p_arm_3_link"/>
    <axis xyz="0 0 1"/>
    <calibration rising="0"/>
    <dynamics damping="5"/>
    <limit effort="176" lower="-2.705260294" upper="2.705260294" velocity="1.25663706144"/>
    <safety_controller k_position="20" k_velocity="25" soft_lower_limit="-6.2731853" soft_upper_limit="6.2731853"/>
  </joint>
  <link name="lwa4p_arm_3_link">
    <inertial>
      <origin rpy="0 0 0" xyz="0 0 0"/>
      <mass value="2.1"/>
      <inertia ixx="0.03" ixy="0" ixz="0" iyy="0.03" iyz="0" izz="0.03"/>
    </inertial>
    <visual>
      <origin rpy="0 0 0" xyz="0 0 0"/>
      <geometry>
        <mesh filename="package://crom_description/meshes/arms/lwa4p/stl/arm_3_link.stl"/>
      </geometry>
      <material name="schunk_light_grey"/>
    </visual>
    <collision>
      <origin rpy="0 0 0" xyz="0 0 0"/>
      <geometry>
        <mesh filename="package://crom_description/meshes/arms/lwa4p/stl/arm_3_link.stl"/>
      </geometry>
    </collision>
  </link>
  <joint name="lwa4p_arm_4_joint" type="revolute">
    <origin rpy="-1.5708 3.14159 0" xyz="0 0 0"/>
    <parent link="lwa4p_arm_3_link"/>
    <child link="lwa4p_arm_4_link"/>
    <axis xyz="0 0 1"/>
    <calibration rising="0"/>
    <dynamics damping="5"/>
    <limit effort="176" lower="-2.967059678" upper="2.967059678" velocity="1.25663706144"/>
    <safety_controller k_position="20" k_velocity="25" soft_lower_limit="-2.0843951" soft_upper_limit="2.0843951"/>
  </joint>
  <link name="lwa4p_arm_4_link">
    <inertial>
      <origin rpy="0 0 0" xyz="0 0 0"/>
      <mass value="1.68311"/>
      <inertia ixx="0.03" ixy="0" ixz="0" iyy="0.03" iyz="0" izz="0.03"/>
    </inertial>
    <visual>
      <origin rpy="0 0 0" xyz="0 0 0"/>
      <geometry>
        <mesh filename="package://crom_description/meshes/arms/lwa4p/stl/arm_4_link.stl"/>
      </geometry>
      <material name="schunk_blue"/>
    </visual>
    <collision>
      <origin rpy="0 0 0" xyz="0 0 0"/>
      <geometry>
        <mesh filename="package://crom_description/meshes/arms/lwa4p/stl/arm_4_link.stl"/>
      </geometry>
    </collision>
  </link>
  <joint name="lwa4p_arm_5_joint" type="revolute">
    <origin rpy="1.5708 0 3.14159" xyz="0 0.005263 0.305"/>
    <parent link="lwa4p_arm_4_link"/>
    <child link="lwa4p_arm_5_link"/>
    <axis xyz="0 0 1"/>
    <calibration rising="0"/>
    <dynamics damping="5"/>
    <limit effort="41.6" lower="-2.51327408" upper="2.51327408" velocity="1.57079632679"/>
    <safety_controller k_position="20" k_velocity="25" soft_lower_limit="-6.2731853" soft_upper_limit="6.2731853"/>
  </joint>
  <link name="lwa4p_arm_5_link">
    <inertial>
      <origin rpy="0 0 0" xyz="0 0 0"/>
      <mass value="0.807"/>
      <inertia ixx="0.03" ixy="0" ixz="0" iyy="0.03" iyz="0" izz="0.03"/>
    </inertial>
    <visual>
      <origin rpy="0 0 0" xyz="0 0 0"/>
      <geometry>
        <mesh filename="package://crom_description/meshes/arms/lwa4p/stl/arm_5_link.stl"/>
      </geometry>
      <material name="schunk_light_grey"/>
    </visual>
    <collision>
      <origin rpy="0 0 0" xyz="0 0 0"/>
      <geometry>
        <mesh filename="package://crom_description/meshes/arms/lwa4p/stl/arm_5_link.stl"/>
      </geometry>
    </collision>
  </link>
  <joint name="lwa4p_arm_6_joint" type="revolute">
    <origin rpy="-1.5708 0 0" xyz="0 0 0"/>
    <parent link="lwa4p_arm_5_link"/>
    <child link="lwa4p_arm_6_link"/>
    <axis xyz="0 0 1"/>
    <calibration rising="0"/>
    <dynamics damping="5"/>
    <limit effort="20.1" lower="-2.967059678" upper="2.967059678" velocity="1.57079632679"/>
    <safety_controller k_position="20" k_velocity="25" soft_lower_limit="-2.0843951" soft_upper_limit="2.0843951"/>
  </joint>
  <link name="lwa4p_arm_6_link">
    <inertial>
      <origin rpy="0 0 0" xyz="0 0 0"/>
      <mass value="0.819"/>
      <inertia ixx="0.01" ixy="0" ixz="0" iyy="0.01" iyz="0" izz="0.01"/>
    </inertial>
    <visual>
      <origin rpy="0 0 0" xyz="0 0 0"/>
      <geometry>
        <mesh filename="package://crom_description/meshes/arms/lwa4p/stl/arm_6_link.stl"/>
      </geometry>
      <material name="schunk_light_grey"/>
    </visual>
    <collision>
      <origin rpy="0 0 0" xyz="0 0 0"/>
      <geometry>
        <mesh filename="package://crom_description/meshes/arms/lwa4p/stl/arm_6_link.stl"/>
      </geometry>
    </collision>
  </link>
  <gazebo reference="lwa4p_arm_0_link">
    <material>Gazebo/Grey</material>
    <turnGravityOff>false</turnGravityOff>
    <selfCollide>true</selfCollide>
  </gazebo>
  <gazebo reference="lwa4p_arm_1_link">
    <material>Gazebo/Grey</material>
    <turnGravityOff>false</turnGravityOff>
    <selfCollide>true</selfCollide>
  </gazebo>
  <gazebo reference="lwa4p_arm_2_link">
    <material>Gazebo/Blue</material>
    <turnGravityOff>false</turnGravityOff>
    <selfCollide>true</selfCollide>
  </gazebo>
  <gazebo reference="lwa4p_arm_3_link">
    <material>Gazebo/Grey</material>
    <turnGravityOff>false</turnGravityOff>
    <selfCollide>true</selfCollide>
  </gazebo>
  <gazebo reference="lwa4p_arm_4_link">
    <material>Gazebo/Blue</material>
    <turnGravityOff>false</turnGravityOff>
    <selfCollide>true</selfCollide>
  </gazebo>
  <gazebo reference="lwa4p_arm_5_link">
    <material>Gazebo/Grey</material>
    <turnGravityOff>false</turnGravityOff>
    <selfCollide>true</selfCollide>
  </gazebo>
  <gazebo reference="lwa4p_arm_6_link">
    <material>Gazebo/Grey</material>
    <turnGravityOff>false</turnGravityOff>
    <selfCollide>true</selfCollide>
  </gazebo>
  <transmission name="lwa4p_arm_1_trans">
    <type>transmission_interface/SimpleTransmission</type>
    <joint name="lwa4p_arm_1_joint"/>
    <actuator name="lwa4p_arm_1_motor">
      <hardwareInterface>PositionJointInterface</hardwareInterface>
      <mechanicalReduction>1</mechanicalReduction>
    </actuator>
  </transmission>
  <transmission name="lwa4p_arm_2_trans">
    <type>transmission_interface/SimpleTransmission</type>
    <joint name="lwa4p_arm_2_joint"/>
    <actuator name="lwa4p_arm_2_motor">
      <hardwareInterface>PositionJointInterface</hardwareInterface>
      <mechanicalReduction>1</mechanicalReduction>
    </actuator>
  </transmission>
  <transmission name="lwa4p_arm_3_trans">
    <type>transmission_interface/SimpleTransmission</type>
    <joint name="lwa4p_arm_3_joint"/>
    <actuator name="lwa4p_arm_3_motor">
      <hardwareInterface>PositionJointInterface</hardwareInterface>
      <mechanicalReduction>1</mechanicalReduction>
    </actuator>
  </transmission>
  <transmission name="lwa4p_arm_4_trans">
    <type>transmission_interface/SimpleTransmission</type>
    <joint name="lwa4p_arm_4_joint"/>
    <actuator name="lwa4p_arm_4_motor">
      <hardwareInterface>PositionJointInterface</hardwareInterface>
      <mechanicalReduction>1</mechanicalReduction>
    </actuator>
  </transmission>
  <transmission name="lwa4p_arm_5_trans">
    <type>transmission_interface/SimpleTransmission</type>
    <joint name="lwa4p_arm_5_joint"/>
    <actuator name="lwa4p_arm_5_motor">
      <hardwareInterface>PositionJointInterface</hardwareInterface>
      <mechanicalReduction>1</mechanicalReduction>
    </actuator>
  </transmission>
  <transmission name="lwa4p_arm_6_trans">
    <type>transmission_interface/SimpleTransmission</type>
    <joint name="lwa4p_arm_6_joint"/>
    <actuator name="lwa4p_arm_6_motor">
      <hardwareInterface>PositionJointInterface</hardwareInterface>
      <mechanicalReduction>1</mechanicalReduction>
    </actuator>
  </transmission>
</robot>

